Traceback (most recent call last):
  File "/gpfs0/jdubi/users/kasirer/home/.local/lib/python3.7/site-packages/matplotlib/animation.py", line 161, in __getitem__
    return self.avail[name]
KeyError: 'ffmpeg'

During handling of the above exception, another exception occurred:

Traceback (most recent call last):
  File "toyModel.py", line 618, in <module>
    voltageTime=voltageTime, output_folder=options.output_folder)
  File "toyModel.py", line 514, in runModel
    Writer = animation.writers['ffmpeg']
  File "/gpfs0/jdubi/users/kasirer/home/.local/lib/python3.7/site-packages/matplotlib/animation.py", line 164, in __getitem__
    'Requested MovieWriter ({}) not available'.format(name))
RuntimeError: Requested MovieWriter (ffmpeg) not available
