multiprocessing.pool.RemoteTraceback: 
"""
Traceback (most recent call last):
  File "/gpfs0/jdubi/users/kasirer/Python-3.7/lib/python3.7/multiprocessing/pool.py", line 121, in worker
    result = (True, func(*args, **kwds))
  File "dots_array_new.py", line 1598, in runSingleSimulation
    currentMap=currentMap, basePath=basePath, resume=resume)
  File "dots_array_new.py", line 1199, in calcIV
    resumeParams = self.loadState(fullOutput=fullOutput, currentMap=currentMap, basePath=basePath)
  File "dots_array_new.py", line 1135, in loadState
    I = np.load(baseName + "_I.npy")
  File "/gpfs0/jdubi/users/kasirer/home/.local/lib/python3.7/site-packages/numpy/lib/npyio.py", line 415, in load
    fid = open(os_fspath(file), "rb")
FileNotFoundError: [Errno 2] No such file or directory: '2d_array_bgu_with_perp_avg/array_10_10_cg_c_disorder_run_1_temp_0_I.npy'
"""

The above exception was the direct cause of the following exception:

Traceback (most recent call last):
  File "dots_array_new.py", line 2247, in <module>
    modifyR=modifyR, constQ=constQ)
  File "dots_array_new.py", line 1719, in runFullSimulation
    result = res.get()
  File "/gpfs0/jdubi/users/kasirer/Python-3.7/lib/python3.7/multiprocessing/pool.py", line 657, in get
    raise self._value
FileNotFoundError: [Errno 2] No such file or directory: '2d_array_bgu_with_perp_avg/array_10_10_cg_c_disorder_run_1_temp_0_I.npy'
