multiprocessing.pool.RemoteTraceback: 
"""
Traceback (most recent call last):
  File "/gpfs0/jdubi/users/kasirer/Python-3.7/lib/python3.7/multiprocessing/pool.py", line 121, in worker
    result = (True, func(*args, **kwds))
  File "dots_array.py", line 1575, in runSingleSimulation
    currentMap=currentMap, basePath=basePath, resume=resume)
  File "dots_array.py", line 1192, in calcIV
    resumeParams = self.loadState(fullOutput=fullOutput, currentMap=currentMap, basePath=basePath)
  File "dots_array.py", line 1150, in loadState
    ns = ns[:, loadLen, :, :]
IndexError: too many indices for array
"""

The above exception was the direct cause of the following exception:

Traceback (most recent call last):
  File "dots_array.py", line 2127, in <module>
    modifyR=modifyR, constQ=constQ)
  File "dots_array.py", line 1688, in runFullSimulation
    result = res.get()
  File "/gpfs0/jdubi/users/kasirer/Python-3.7/lib/python3.7/multiprocessing/pool.py", line 657, in get
    raise self._value
IndexError: too many indices for array
