multiprocessing.pool.RemoteTraceback: 
"""
Traceback (most recent call last):
  File "/gpfs0/jdubi/users/kasirer/home/.local/lib/python3.7/site-packages/numpy/lib/npyio.py", line 447, in load
    return pickle.load(fid, **pickle_kwargs)
EOFError: Ran out of input

During handling of the above exception, another exception occurred:

Traceback (most recent call last):
  File "/gpfs0/jdubi/users/kasirer/Python-3.7/lib/python3.7/multiprocessing/pool.py", line 121, in worker
    result = (True, func(*args, **kwds))
  File "dots_array.py", line 1575, in runSingleSimulation
    currentMap=currentMap, basePath=basePath, resume=resume)
  File "dots_array.py", line 1192, in calcIV
    resumeParams = self.loadState(fullOutput=fullOutput, currentMap=currentMap, basePath=basePath)
  File "dots_array.py", line 1148, in loadState
    ns = np.load(baseName + "_ns.npy")
  File "/gpfs0/jdubi/users/kasirer/home/.local/lib/python3.7/site-packages/numpy/lib/npyio.py", line 450, in load
    "Failed to interpret file %s as a pickle" % repr(file))
OSError: Failed to interpret file '2d_array_bgu/array_10_10_r_disorder_cg_disorder_run_3_temp_3_ns.npy' as a pickle
"""

The above exception was the direct cause of the following exception:

Traceback (most recent call last):
  File "dots_array.py", line 2127, in <module>
    modifyR=modifyR, constQ=constQ)
  File "dots_array.py", line 1688, in runFullSimulation
    result = res.get()
  File "/gpfs0/jdubi/users/kasirer/Python-3.7/lib/python3.7/multiprocessing/pool.py", line 657, in get
    raise self._value
OSError: Failed to interpret file '2d_array_bgu/array_10_10_r_disorder_cg_disorder_run_3_temp_3_ns.npy' as a pickle
