multiprocessing.pool.RemoteTraceback: 
"""
Traceback (most recent call last):
  File "/gpfs0/jdubi/users/kasirer/Python-3.7/lib/python3.7/multiprocessing/pool.py", line 121, in worker
    result = (True, func(*args, **kwds))
  File "dots_array.py", line 1559, in runSingleSimulation
    currentMap=currentMap, basePath=basePath, resume=resume)
  File "dots_array.py", line 1195, in calcIV
    self.getToSteadyState()
  File "dots_array.py", line 1042, in getToSteadyState
    dt = self.executeStep()
  File "dots_array.py", line 893, in executeStep
    dt, intervals = self.dotArray.getTimeInterval(r[0])
  File "dots_array.py", line 599, in getTimeInterval
    rates = self.getRates()
  File "dots_array.py", line 545, in getRates
    self.modifyR()
  File "dots_array.py", line 585, in modifyR
    self.R[2*horzSize:2*horzSize+vertSize] = (self.Rv*nExponent[:-1,:]).flatten()
ValueError: operands could not be broadcast together with shapes (0,0) (0,10) 
"""

The above exception was the direct cause of the following exception:

Traceback (most recent call last):
  File "dots_array.py", line 2111, in <module>
    modifyR=modifyR, constQ=constQ)
  File "dots_array.py", line 1672, in runFullSimulation
    result = res.get()
  File "/gpfs0/jdubi/users/kasirer/Python-3.7/lib/python3.7/multiprocessing/pool.py", line 657, in get
    raise self._value
ValueError: operands could not be broadcast together with shapes (0,0) (0,10) 
