multiprocessing.pool.RemoteTraceback: 
"""
Traceback (most recent call last):
  File "/gpfs0/jdubi/users/kasirer/Python-3.7/lib/python3.7/multiprocessing/pool.py", line 121, in worker
    result = (True, func(*args, **kwds))
  File "dots_array.py", line 1578, in runSingleSimulation
    currentMap=currentMap, basePath=basePath, resume=resume)
  File "dots_array.py", line 1214, in calcIV
    self.getToSteadyState()
  File "dots_array.py", line 1059, in getToSteadyState
    dt = self.executeStep()
  File "dots_array.py", line 909, in executeStep
    dt, intervals = self.dotArray.getTimeInterval(r[0])
  File "dots_array.py", line 613, in getTimeInterval
    rates = self.getRates()
  File "dots_array.py", line 559, in getRates
    self.rates = -work / self.R
ValueError: operands could not be broadcast together with shapes (400,) (238,) 
"""

The above exception was the direct cause of the following exception:

Traceback (most recent call last):
  File "dots_array.py", line 2180, in <module>
    modifyR=modifyR, constQ=constQ)
  File "dots_array.py", line 1695, in runFullSimulation
    result = res.get()
  File "/gpfs0/jdubi/users/kasirer/Python-3.7/lib/python3.7/multiprocessing/pool.py", line 657, in get
    raise self._value
ValueError: operands could not be broadcast together with shapes (400,) (238,) 
