multiprocessing.pool.RemoteTraceback: 
"""
Traceback (most recent call last):
  File "/gpfs0/jdubi/users/kasirer/Python-3.7/lib/python3.7/multiprocessing/pool.py", line 121, in worker
    result = (True, func(*args, **kwds))
  File "dots_array.py", line 1740, in runSingleSimulation
    double_loop=double_loop)
  File "dots_array.py", line 1347, in calcIV
    currentMap=currentMap, basePath=basePath)
  File "dots_array.py", line 1247, in saveState
    np.save(baseName + "_I", np.array(I))
  File "/gpfs0/jdubi/users/kasirer/home/.local/lib/python3.7/site-packages/numpy/lib/npyio.py", line 529, in save
    pickle_kwargs=pickle_kwargs)
  File "/gpfs0/jdubi/users/kasirer/home/.local/lib/python3.7/site-packages/numpy/lib/format.py", line 640, in write_array
    array.tofile(fp)
OSError: 3937 requested and 0 written
"""

The above exception was the direct cause of the following exception:

Traceback (most recent call last):
  File "dots_array.py", line 2472, in <module>
    calcIT=options.calcIT)
  File "dots_array.py", line 1870, in runFullSimulation
    result = res.get()
  File "/gpfs0/jdubi/users/kasirer/Python-3.7/lib/python3.7/multiprocessing/pool.py", line 657, in get
    raise self._value
OSError: 3937 requested and 0 written
