multiprocessing.pool.RemoteTraceback: 
"""
Traceback (most recent call last):
  File "/gpfs0/jdubi/users/kasirer/Python-3.7/lib/python3.7/multiprocessing/pool.py", line 121, in worker
    result = (True, func(*args, **kwds))
  File "dots_array.py", line 1740, in runSingleSimulation
    double_loop=double_loop)
  File "dots_array.py", line 1329, in calcIV
    self.getToSteadyState()
  File "dots_array.py", line 1192, in getToSteadyState
    dt = self.executeStep()
  File "dots_array.py", line 1057, in executeStep
    dt, intervals = self.dotArray.getTimeInterval(r[0])
  File "dots_array.py", line 693, in getTimeInterval
    rates = self.getRates()
  File "dots_array.py", line 931, in getRates
    self.rates[:mid] = self.qp_rate_calculator.get_tunnling_rates(-qp_work) / self.R
  File "dots_array.py", line 281, in get_tunnling_rates
    self.update_rates()
  File "dots_array.py", line 277, in update_rates
    self.freeWritingLock()
  File "dots_array.py", line 205, in freeWritingLock
    os.remove(os.path.join(self.dirName, "writing.txt"))
FileNotFoundError: [Errno 2] No such file or directory: 'quasi_particles_rate/tunneling_rate_0.001_0.5/writing.txt'
"""

The above exception was the direct cause of the following exception:

Traceback (most recent call last):
  File "dots_array.py", line 2472, in <module>
    calcIT=options.calcIT)
  File "dots_array.py", line 1870, in runFullSimulation
    result = res.get()
  File "/gpfs0/jdubi/users/kasirer/Python-3.7/lib/python3.7/multiprocessing/pool.py", line 657, in get
    raise self._value
FileNotFoundError: [Errno 2] No such file or directory: 'quasi_particles_rate/tunneling_rate_0.001_0.5/writing.txt'
