multiprocessing.pool.RemoteTraceback: 
"""
Traceback (most recent call last):
  File "/gpfs0/jdubi/users/kasirer/Python-3.7/lib/python3.7/multiprocessing/pool.py", line 121, in worker
    result = (True, func(*args, **kwds))
  File "dots_array.py", line 498, in runSingleSimulation
    fullOutput=fullOutput, print=printState)
  File "dots_array.py", line 356, in calcIV
    self.calcCurrent(tStep)
  File "dots_array.py", line 323, in calcCurrent
    curr_t += self.executeStep(printState=print)
  File "dots_array.py", line 313, in executeStep
    dt = self.dotArray.getTimeInterval(r[0])
  File "dots_array.py", line 205, in getTimeInterval
    rates = self.getRates()
  File "dots_array.py", line 194, in getRates
    work = self.getWork()
  File "dots_array.py", line 187, in getWork
    q = self.getNprime() + flattenToColumn(self.Q)
  File "dots_array.py", line 111, in getNprime
    return flattenToColumn(self.n + self.left_part_n_prime*self.VL + self.right_part_n_prime*self.VR)
AttributeError: 'DotArray' object has no attribute 'left_part_n_prime'
"""

The above exception was the direct cause of the following exception:

Traceback (most recent call last):
  File "dots_array.py", line 725, in <module>
    savePath=savePath, fileName=fileName, printState=False, useGraph=False)
  File "dots_array.py", line 529, in runFullSimulation
    I, V, params = res.get()
  File "/gpfs0/jdubi/users/kasirer/Python-3.7/lib/python3.7/multiprocessing/pool.py", line 657, in get
    raise self._value
AttributeError: 'DotArray' object has no attribute 'left_part_n_prime'
