multiprocessing.pool.RemoteTraceback: 
"""
Traceback (most recent call last):
  File "/gpfs0/jdubi/users/kasirer/Python-3.7/lib/python3.7/multiprocessing/pool.py", line 121, in worker
    result = (True, func(*args, **kwds))
  File "dots_array.py", line 778, in runSingleSimulation
    fullOutput=fullOutput, print_stats=printState, currentMap=currentMap)
  File "dots_array.py", line 494, in calcIV
    self.calcCurrent(tStep)
  File "dots_array.py", line 444, in calcCurrent
    dt = self.executeStep(printState=print_stats)
  File "dots_array.py", line 424, in executeStep
    dt = self.dotArray.getTimeInterval(r[0])
  File "dots_array.py", line 303, in getTimeInterval
    rates = self.getRates()
  File "dots_array.py", line 287, in getRates
    return -work / self.R
ValueError: operands could not be broadcast together with shapes (100,) (16,) 
"""

The above exception was the direct cause of the following exception:

Traceback (most recent call last):
  File "dots_array.py", line 1095, in <module>
    dbg=dbg, plotCurrentMaps=plot_current_map)
  File "dots_array.py", line 815, in runFullSimulation
    result = res.get()
  File "/gpfs0/jdubi/users/kasirer/Python-3.7/lib/python3.7/multiprocessing/pool.py", line 657, in get
    raise self._value
ValueError: operands could not be broadcast together with shapes (100,) (16,) 
