
python3 dots_array.py -M 3 -N 3 --vmin 0 --vmax 2 --vstep 0.01 --vr 0 --vg-avg 0 --vg-std 0 --c-avg 1 --c-std 0.1 --cg-avg 10 --cg-std 0 --r-avg 1 --r-std 2 --rg-avg 1000 --rg-std 0 --repeats 20 --n-avg 0 --n-std 0 --q-avg 0 --q-std 0 -T 0 --distribution exp --custom-rh "" --custom-rv "" --custom-ch "" --custom-cv "" --file-name c_std_0.1_r_std_2_run_1 -o 3X3_array_statistics    --resume --symmetric-v

Loading array parameters
Normal prototype array was created
Starting parallel run
total steps = 1149257
total steps = 957822
total steps = 1530863
total steps = 1310852
total steps = 1453941
total steps = 1530863
total steps = 1530863
total steps = 1256438
total steps = 1823027
total steps = 1687902
total steps = 1923233
multiprocessing.pool.RemoteTraceback: 
"""
Traceback (most recent call last):
  File "/usr/local/anaconda3/lib/python3.7/multiprocessing/pool.py", line 121, in worker
    result = (True, func(*args, **kwds))
  File "dots_array.py", line 1222, in runSingleSimulation
    currentMap=currentMap, basePath=basePath, resume=resume)
  File "dots_array.py", line 838, in calcIV
    resumeParams = self.loadState(fullOutput=fullOutput, currentMap=currentMap, basePath=basePath)
  File "dots_array.py", line 799, in loadState
    I = np.load(baseName + "_I.npy")
  File "/usr/local/anaconda3/lib/python3.7/site-packages/numpy/lib/npyio.py", line 384, in load
    fid = open(file, "rb")
FileNotFoundError: [Errno 2] No such file or directory: '3X3_array_statistics/c_std_0.1_r_std_2_run_1_temp_2_I.npy'
"""

The above exception was the direct cause of the following exception:

Traceback (most recent call last):
  File "dots_array.py", line 1672, in <module>
    checkSteadyState=False, superconducting=sc, gap=gap)
  File "dots_array.py", line 1320, in runFullSimulation
    result = res.get()
  File "/usr/local/anaconda3/lib/python3.7/multiprocessing/pool.py", line 683, in get
    raise self._value
FileNotFoundError: [Errno 2] No such file or directory: '3X3_array_statistics/c_std_0.1_r_std_2_run_1_temp_2_I.npy'
