
python3 dots_array.py -M 2 -N 1 --vmin 0 --vmax 30 --vstep 0.1 --vr 0 --vg-avg 0 --vg-std 0 --c-avg 1 --c-std 0.5 --cg-avg 10 --cg-std 0 --r-avg 10 --r-std 0 --rg-avg 1000 --rg-std 0 --repeats 20 --n-avg 0 --n-std 0 --q-avg 0 --q-std 0 --distribution uniform --custom-rh "[[10,1],[]]" --custom-rv "[[1]]" --file-name zigzag_r_2_1 -o 2_dots_arrays_c_disorder_high_v --full  

multiprocessing.pool.RemoteTraceback: 
"""
Traceback (most recent call last):
  File "/usr/local/anaconda3/lib/python3.7/multiprocessing/pool.py", line 121, in worker
    result = (True, func(*args, **kwds))
  File "dots_array.py", line 913, in runSingleSimulation
    currentMap=currentMap, basePath=basePath, resume=resume)
  File "dots_array.py", line 571, in calcIV
    self.calcCurrent(tStep)
  File "dots_array.py", line 467, in calcCurrent
    dt = self.executeStep(printState=print_stats)
  File "dots_array.py", line 447, in executeStep
    dt = self.dotArray.getTimeInterval(r[0])
  File "dots_array.py", line 325, in getTimeInterval
    rates = self.getRates()
  File "dots_array.py", line 308, in getRates
    return -work / self.R
ValueError: operands could not be broadcast together with shapes (10,) (6,) 
"""

The above exception was the direct cause of the following exception:

Traceback (most recent call last):
  File "dots_array.py", line 1282, in <module>
    dbg=dbg, plotCurrentMaps=plot_current_map, resume=resume)
  File "dots_array.py", line 997, in runFullSimulation
    result = res.get()
  File "/usr/local/anaconda3/lib/python3.7/multiprocessing/pool.py", line 683, in get
    raise self._value
ValueError: operands could not be broadcast together with shapes (10,) (6,) 
