
python3 dots_array.py -M 1 -N 2 --vmin -2 --vmax 2 --vstep 0.1 --vr 0 --vg-avg 0 --vg-std 0 --c-avg 1 --c-std 0 --cg-avg 10 --cg-std 0 --r-avg 10 --r-std 0 --rg-avg 1000 --rg-std 0 --repeats 1 --n-avg 0 --n-std 0 --q-avg 0 --q-std 0 --distribution two_points --custom-rh "[[1,10,20]]" --custom-rv "[[]]" --file-name increasing_r -o 2_dots_arrays_with_graph   --graph

multiprocessing.pool.RemoteTraceback: 
"""
Traceback (most recent call last):
  File "/usr/local/anaconda3/lib/python3.7/multiprocessing/pool.py", line 121, in worker
    result = (True, func(*args, **kwds))
  File "dots_array.py", line 651, in runSingleSimulation
    fullOutput=fullOutput, print_stats=printState, currentMap=currentMap)
  File "dots_array.py", line 631, in calcIV
    rightCurrent, leftCurrnet = self.calcCurrent()
  File "dots_array.py", line 596, in calcCurrent
    self.find_next_QG()
  File "dots_array.py", line 593, in find_next_QG
    self.QG = self.Q_grid[peaks][Qind]
IndexError: index 40000 is out of bounds for axis 0 with size 40000
"""

The above exception was the direct cause of the following exception:

Traceback (most recent call last):
  File "dots_array.py", line 954, in <module>
    dbg=dbg)
  File "dots_array.py", line 682, in runFullSimulation
    result = res.get()
  File "/usr/local/anaconda3/lib/python3.7/multiprocessing/pool.py", line 683, in get
    raise self._value
IndexError: index 40000 is out of bounds for axis 0 with size 40000
