
python3 dots_array.py -M 5 -N 5 --vmin 0 --vmax 5 --vstep 0.01 --vr 0 --vg-avg 0 --vg-std 0 --c-avg 1 --c-std 0 --cg-avg 10 --cg-std 0 --r-avg 10 --r-std 9 --rg-avg 1000 --rg-std 0 --repeats 20 --n-avg 0 --n-std 0 --q-avg 0 --q-std 0 --distribution uniform --custom-rh "[[10,10,10],[1,1,1]]" --custom-rv "[[10,10]]" --file-name one_nig_one_small_2_2 -o 2D_square_arrays_with_current_map  --current-map 

multiprocessing.pool.RemoteTraceback: 
"""
Traceback (most recent call last):
  File "/usr/local/anaconda3/lib/python3.7/multiprocessing/pool.py", line 121, in worker
    result = (True, func(*args, **kwds))
  File "dots_array.py", line 778, in runSingleSimulation
    fullOutput=fullOutput, print_stats=printState, currentMap=currentMap)
  File "dots_array.py", line 494, in calcIV
    self.calcCurrent(tStep)
  File "dots_array.py", line 444, in calcCurrent
    dt = self.executeStep(printState=print_stats)
  File "dots_array.py", line 424, in executeStep
    dt = self.dotArray.getTimeInterval(r[0])
  File "dots_array.py", line 303, in getTimeInterval
    rates = self.getRates()
  File "dots_array.py", line 287, in getRates
    return -work / self.R
ValueError: operands could not be broadcast together with shapes (100,) (16,) 
"""

The above exception was the direct cause of the following exception:

Traceback (most recent call last):
  File "dots_array.py", line 1095, in <module>
    dbg=dbg, plotCurrentMaps=plot_current_map)
  File "dots_array.py", line 815, in runFullSimulation
    result = res.get()
  File "/usr/local/anaconda3/lib/python3.7/multiprocessing/pool.py", line 683, in get
    raise self._value
ValueError: operands could not be broadcast together with shapes (100,) (16,) 
