
python3 dots_array.py -M 5 -N 5 --vmin 0 --vmax 5 --vstep 0.01 --vr 0 --vg-avg 0 --vg-std 0 --c-avg 1 --c-std 0 --cg-avg 10 --cg-std 0 --r-avg 10 --r-std 9 --rg-avg 1000 --rg-std 0 --repeats 20 --n-avg 0 --n-std 0 --q-avg 0 --q-std 0 --distribution two_points --custom-rh "" --custom-rv "" --file-name two_points_disorder_5_5 -o 2D_square_arrays_with_current_map  --current-map

multiprocessing.pool.RemoteTraceback: 
"""
Traceback (most recent call last):
  File "/usr/local/anaconda3/lib/python3.7/multiprocessing/pool.py", line 121, in worker
    result = (True, func(*args, **kwds))
  File "dots_array.py", line 643, in runSingleSimulation
    fullOutput=fullOutput, print=printState, currentMap=currentMap)
  File "dots_array.py", line 443, in calcIV
    self.calcCurrent(tStep)
  File "dots_array.py", line 393, in calcCurrent
    dt = self.executeStep(printState=print)
  File "dots_array.py", line 373, in executeStep
    dt = self.dotArray.getTimeInterval(r[0])
  File "dots_array.py", line 252, in getTimeInterval
    rates = self.getRates()
  File "dots_array.py", line 242, in getRates
    return -work / self.R
TypeError: ufunc 'true_divide' not supported for the input types, and the inputs could not be safely coerced to any supported types according to the casting rule ''safe''
"""

The above exception was the direct cause of the following exception:

Traceback (most recent call last):
  File "dots_array.py", line 952, in <module>
    printState=False, useGraph=use_graph, fastRelaxation=fast_relaxation, currentMap=current_map)
  File "dots_array.py", line 675, in runFullSimulation
    result=res.get()
  File "/usr/local/anaconda3/lib/python3.7/multiprocessing/pool.py", line 683, in get
    raise self._value
TypeError: ufunc 'true_divide' not supported for the input types, and the inputs could not be safely coerced to any supported types according to the casting rule ''safe''
